Traceback (most recent call last):
  File "/gpfs/apps/icl/software/Anaconda3/2024.06-1/lib/python3.12/site-packages/pandas/core/indexes/base.py", line 3805, in get_loc
    return self._engine.get_loc(casted_key)
           ^^^^^^^^^^^^^^^^^^^^^^^^^^^^^^^^
  File "index.pyx", line 167, in pandas._libs.index.IndexEngine.get_loc
  File "index.pyx", line 196, in pandas._libs.index.IndexEngine.get_loc
  File "pandas/_libs/hashtable_class_helper.pxi", line 7081, in pandas._libs.hashtable.PyObjectHashTable.get_item
  File "pandas/_libs/hashtable_class_helper.pxi", line 7089, in pandas._libs.hashtable.PyObjectHashTable.get_item
KeyError: 'PRScs_alda'

The above exception was the direct cause of the following exception:

Traceback (most recent call last):
  File "/hpcfs/users/a1236780/Repos/LiPGS/src/pipeline.py", line 282, in <module>
    main()
  File "/hpcfs/users/a1236780/Repos/LiPGS/src/pipeline.py", line 279, in main
    merge_files(args)
  File "/hpcfs/users/a1236780/Repos/LiPGS/src/pipeline.py", line 234, in merge_files
    mean_prs = df_merged[f'PRScs_{args.pheno_type}'].mean()
               ~~~~~~~~~^^^^^^^^^^^^^^^^^^^^^^^^^^^^
  File "/gpfs/apps/icl/software/Anaconda3/2024.06-1/lib/python3.12/site-packages/pandas/core/frame.py", line 4102, in __getitem__
    indexer = self.columns.get_loc(key)
              ^^^^^^^^^^^^^^^^^^^^^^^^^
  File "/gpfs/apps/icl/software/Anaconda3/2024.06-1/lib/python3.12/site-packages/pandas/core/indexes/base.py", line 3812, in get_loc
    raise KeyError(key) from err
KeyError: 'PRScs_alda'
